Workbook
Name العملية: العملية!$A$1:$A$25

Sheet 01-04
I1: حركة الصندوق | J1: =SUM(J3:J11) -> 340 | K1: =SUM(K3:K11) -> 200 | L1: =SUM(L3:L11) -> 203.77778
H2: العملية | I2: البيان | J2: اللبناني | K2: الدولار | L2: مبيع $
H3: بيع | J3: 400 | L3: =K3+(J3/90) -> 4.4444444
H4: بيع | J4: 300 | L4: =K4+(J4/90) -> 3.3333333
H5: بيع | J5: -360 | K5: 200 | L5: =K5+(J5/90) -> 196
H6: بيع | L6: =K6+(J6/90) -> 0
H7: بيع | L7: =K7+(J7/90) -> 0
L8: =K8+(J8/90) -> 0
L9: =K9+(J9/90) -> 0
L10: =K10+(J10/90) -> 0
A11: جرد اول النهار | L11: =K11+(J11/90) -> 0 | N11: جرد اخر النهار
A12: الفئة دولار | B12: العدد | C12: المجموع | D12: الفئة لبناني | E12: العدد | F12: المجموع | I12: البيان | J12: اللبناني | K12: الدولار | L12: مبيع $ | N12: الفئة دولار | O12: العدد | P12: المجموع | Q12: الفئة لبناني | R12: العدد | S12: المجموع
A13: 1 | B13: 1 | C13: =A13*B13 -> 1 | D13: 5 | E13: 44 | F13: =D13*E13 -> 220 | H13: بيع | I13: سبراي | J13: 140 | L13: ='01-04'!$K13+('01-04'!$J13/90) -> 1.5555556 | N13: 1 | P13: =N13*O13 -> 0 | Q13: 5 | R13: 48 | S13: =Q13*R13 -> 240
A14: 5 | B14: 6 | C14: =A14*B14 -> 30 | D14: 10 | E14: 28 | F14: =D14*E14 -> 280 | H14: بيع | I14: غطاء فينيسيا | K14: 10 | L14: ='01-04'!$K14+('01-04'!$J14/90) -> 10 | N14: 5 | O14: 5 | P14: =N14*O14 -> 25 | Q14: 10 | R14: 32 | S14: =Q14*R14 -> 320
A15: 10 | B15: 59 | C15: =A15*B15 -> 590 | D15: 20 | E15: 14 | F15: =D15*E15 -> 280 | H15: بيع | I15: - | J15: -10 | L15: ='01-04'!$K15+('01-04'!$J15/90) -> -0.11111111 | N15: 10 | O15: 61 | P15: =N15*O15 -> 610 | Q15: 20 | R15: 13 | S15: =Q15*R15 -> 260
A16: 20 | B16: 5 | C16: =A16*B16 -> 100 | D16: 50 | F16: =D16*E16 -> 0 | H16: بيع | I16: محمود سلامة | J16: 1080 | L16: ='01-04'!$K16+('01-04'!$J16/90) -> 12 | N16: 20 | O16: 5 | P16: =N16*O16 -> 100 | Q16: 50 | S16: =Q16*R16 -> 0
A17: 50 | C17: =A17*B17 -> 0 | D17: 100 | E17: 55 | F17: =D17*E17 -> 5500 | H17: بيع | I17: ابو حسين سلامة | J17: -360 | K17: 85 | L17: ='01-04'!$K17+('01-04'!$J17/90) -> 81 | N17: 50 | O17: 2 | P17: =N17*O17 -> 100 | Q17: 100 | R17: 37 | S17: =Q17*R17 -> 3700
A18: 100 | B18: 3 | C18: =A18*B18 -> 300 | D18: المجموع | F18: =SUM(F13:F17) -> 6280 | H18: بيع | I18: وجيه | J18: -50 | L18: ='01-04'!$K18+('01-04'!$J18/90) -> -0.55555556 | N18: 100 | O18: 4 | P18: =N18*O18 -> 400 | Q18: المجموع | S18: =SUM(S13:S17) -> 4520
A19: المجموع | C19: =SUM(C13:C18) -> 1021 | H19: بيع | I19: جوان حصر وايزي | J19: 200 | L19: ='01-04'!$K19+('01-04'!$J19/90) -> 2.2222222 | N19: المجموع | P19: =SUM(P13:P18) -> 1235
H20: بيع | I20: تلزيق بلاط وطني | J20: 100 | K20: 20 | L20: ='01-04'!$K20+('01-04'!$J20/90) -> 21.111111 | Q20: حركة الصندوق ل.ل | S20: =SUM('01-04'!$J$13:$J$100) -> -3760
H21: بيع | I21: مسكة فيتاس | J21: 200 | L21: ='01-04'!$K21+('01-04'!$J21/90) -> 2.2222222 | N21: حركة الصندوق $ | P21: =SUM('01-04'!$K$13:$K$100) -> -370
H22: بيع | I22: خلاط دوش+سكر | K22: 25 | L22: ='01-04'!$K22+('01-04'!$J22/90) -> 25 | Q22: الفرق | S22: =S18-S20-F18 -> 2000
H23: بيع | I23: طابة سوداء | J23: -350 | K23: 5 | L23: ='01-04'!$K23+('01-04'!$J23/90) -> 1.1111111 | N23: الفرق | P23: =P19-P21-C19 -> 584
H24: بيع | I24: قطع وصل | K24: 34 | L24: ='01-04'!$K24+('01-04'!$J24/90) -> 34
H25: مصاريف | I25: بنزين ابراهيم | J25: -300 | L25: ='01-04'!$K25+('01-04'!$J25/90) -> -3.3333333
H26: بيع | I26: - | J26: -300 | K26: 5 | L26: ='01-04'!$K26+('01-04'!$J26/90) -> 1.6666667
H27: بيع | I27: عنق | J27: 350 | L27: ='01-04'!$K27+('01-04'!$J27/90) -> 3.8888889
H28: بيع | I28: نربيج شطافة | J28: 500 | L28: ='01-04'!$K28+('01-04'!$J28/90) -> 5.5555556
H29: بيع | I29: سوناكس | J29: -700 | K29: 10 | L29: ='01-04'!$K29+('01-04'!$J29/90) -> 2.2222222
H30: بيع | I30: ورق حف | J30: 270 | L30: ='01-04'!$K30+('01-04'!$J30/90) -> 3
H31: بيع | I31: علبة باتكس | J31: 270 | L31: ='01-04'!$K31+('01-04'!$J31/90) -> 3
H32: مصاريف | I32: بنزين عبد | J32: -300 | L32: ='01-04'!$K32+('01-04'!$J32/90) -> -3.3333333
H33: بيع | I33: تطويلة غروهي | J33: -360 | K33: 10 | L33: ='01-04'!$K33+('01-04'!$J33/90) -> 6
H34: بيع | I34: تفلون | J34: 70 | L34: ='01-04'!$K34+('01-04'!$J34/90) -> 0.77777778
H35: بيع | I35: نربيج غاز وحبسة | J35: 200 | L35: ='01-04'!$K35+('01-04'!$J35/90) -> 2.2222222
H36: بيع | I36: احمد القيسي | J36: 45 | K36: 10 | L36: ='01-04'!$K36+('01-04'!$J36/90) -> 10.5
H37: سحب | I37: للحاج اشتراك | K37: -110 | L37: ='01-04'!$K37+('01-04'!$J37/90) -> -110
H38: بيع | I38: بطاريات | K38: -55 | L38: ='01-04'!$K38+('01-04'!$J38/90) -> -55
H39: مصاريف | I39: بنزين حسام | J39: -2000 | L39: ='01-04'!$K39+('01-04'!$J39/90) -> -22.222222
H40: بيع | I40: شبك ورباطات | J40: 100 | K40: 15 | L40: ='01-04'!$K40+('01-04'!$J40/90) -> 16.111111
...

Sheet 02-04
I1: حركة الصندوق | J1: =SUM(J3:J11) -> 600 | K1: =SUM(K3:K11) -> 90 | L1: =SUM(L3:L11) -> 96.666667
H2: العملية | I2: البيان | J2: اللبناني | K2: الدولار | L2: مبيع $
H3: بيع | I3: لقمان | K3: 80 | L3: =K3+(J3/90) -> 80
H4: بيع | J4: 150 | L4: =K4+(J4/90) -> 1.6666667
H5: بيع | J5: -150 | K5: 10 | L5: =K5+(J5/90) -> 8.3333333
H6: بيع | J6: 300 | L6: =K6+(J6/90) -> 3.3333333
H7: بيع | I7: رمل | J7: 300 | L7: =K7+(J7/90) -> 3.3333333
L8: =K8+(J8/90) -> 0
L9: =K9+(J9/90) -> 0
L10: =K10+(J10/90) -> 0
L11: =K11+(J11/90) -> 0
A13: جرد اول النهار | I13: حركة الصندوق | J13: =SUM('02-04'!$J$15:$J$138) -> -1345 | K13: =SUM('02-04'!$K$15:$K$138) -> 264 | L13: =SUM('02-04'!$L$15:$L$138) -> 249.05556 | N13: جرد اخر النهار
A14: الفئة دولار | B14: العدد | C14: المجموع | D14: الفئة لبناني | E14: العدد | F14: المجموع | H14: العملية | I14: البيان | J14: اللبناني | K14: الدولار | L14: مبيع $ | N14: الفئة دولار | O14: العدد | P14: المجموع | Q14: الفئة لبناني | R14: العدد | S14: المجموع
A15: 1 | B15: 1 | C15: =A15*B15 -> 1 | D15: 5 | E15: 46 | F15: =D15*E15 -> 230 | H15: بيع | I15: فرشاية | J15: 70 | L15: ='02-04'!$K15+('02-04'!$J15/90) -> 0.77777778 | N15: 1 | P15: =N15*O15 -> 0 | Q15: 5 | R15: 43 | S15: =Q15*R15 -> 215
A16: 5 | C16: =A16*B16 -> 0 | D16: 10 | E16: 27 | F16: =D16*E16 -> 270 | H16: جملة | I16: عماد شعبان | J16: 100 | K16: 76 | L16: ='02-04'!$K16+('02-04'!$J16/90) -> 77.111111 | N16: 5 | O16: 5 | P16: =N16*O16 -> 25 | Q16: 10 | R16: 24 | S16: =Q16*R16 -> 240
A17: 10 | B17: 60 | C17: =A17*B17 -> 600 | D17: 20 | E17: 5 | F17: =D17*E17 -> 100 | H17: مصاريف | I17: بنزين ابراهيم | J17: -300 | L17: ='02-04'!$K17+('02-04'!$J17/90) -> -3.3333333 | N17: 10 | O17: 60 | P17: =N17*O17 -> 600 | Q17: 20 | R17: 5 | S17: =Q17*R17 -> 100
A18: 20 | B18: 2 | C18: =A18*B18 -> 40 | D18: 50 | F18: =D18*E18 -> 0 | H18: بيع | I18: قازان 100 فيلوكس | K18: 115 | L18: ='02-04'!$K18+('02-04'!$J18/90) -> 115 | N18: 20 | O18: 19 | P18: =N18*O18 -> 380 | Q18: 50 | R18: 4 | S18: =Q18*R18 -> 200
A19: 50 | C19: =A19*B19 -> 0 | D19: 100 | E19: 27 | F19: =D19*E19 -> 2700 | H19: بيع | I19: غطاء ريغار | K19: 15 | L19: ='02-04'!$K19+('02-04'!$J19/90) -> 15 | N19: 50 | O19: 2 | P19: =N19*O19 -> 100 | Q19: 100 | R19: 62 | S19: =Q19*R19 -> 6200
A20: 100 | B20: 1 | C20: =A20*B20 -> 100 | D20: المجموع | F20: =SUM(F15:F19) -> 3300 | H20: بيع | I20: متر | J20: 75 | K20: 2 | L20: ='02-04'!$K20+('02-04'!$J20/90) -> 2.8333333 | N20: 100 | O20: 50 | P20: =N20*O20 -> 5000 | Q20: المجموع | S20: =SUM(S15:S19) -> 6955
A21: المجموع | C21: =SUM(C15:C20) -> 741 | H21: بيع | I21: مرتجع حجر | K21: -10 | L21: ='02-04'!$K21+('02-04'!$J21/90) -> -10 | N21: المجموع | P21: =SUM(P15:P20) -> 6105
H22: بيع | I22: باقي رمل | J22: 40 | L22: ='02-04'!$K22+('02-04'!$J22/90) -> 0.44444444 | Q22: حركة الصندوق ل.ل | S22: =SUM('02-04'!$J$15:$J$138) -> -1345
H23: بيع | I23: قلبين ايطالي | J23: -50 | K23: 6 | L23: ='02-04'!$K23+('02-04'!$J23/90) -> 5.4444444 | N23: حركة الصندوق $ | P23: =SUM('02-04'!$K$15:$K$138) -> 264
H24: بيع | J24: -320 | K24: 10 | L24: ='02-04'!$K24+('02-04'!$J24/90) -> 6.4444444 | Q24: الفرق | S24: =S20-S22-F20 -> 5000
H25: بيع | J25: -300 | K25: 5 | L25: ='02-04'!$K25+('02-04'!$J25/90) -> 1.6666667 | N25: الفرق | P25: =P21-P23-C21 -> 5100
H26: بيع | I26: وجيه | K26: 40 | L26: ='02-04'!$K26+('02-04'!$J26/90) -> 40
H27: بيع | J27: 510 | L27: ='02-04'!$K27+('02-04'!$J27/90) -> 5.6666667
H28: بيع | I28: قلب | J28: 100 | L28: ='02-04'!$K28+('02-04'!$J28/90) -> 1.1111111
H29: بيع | J29: 350 | L29: ='02-04'!$K29+('02-04'!$J29/90) -> 3.8888889
H30: بيع | J30: 120 | L30: ='02-04'!$K30+('02-04'!$J30/90) -> 1.3333333
H31: بيع | I31: تلوينة | J31: 100 | L31: ='02-04'!$K31+('02-04'!$J31/90) -> 1.1111111
H32: بيع | I32: زراعي | J32: 250 | L32: ='02-04'!$K32+('02-04'!$J32/90) -> 2.7777778
H33: بيع | I33: خرطوشة فلتر | J33: 420 | L33: ='02-04'!$K33+('02-04'!$J33/90) -> 4.6666667
H34: بيع | I34: بلال مكداشي | J34: 1150 | K34: 100 | L34: ='02-04'!$K34+('02-04'!$J34/90) -> 112.77778
H35: بيع | I35: سيليكون | K35: 2 | L35: ='02-04'!$K35+('02-04'!$J35/90) -> 2
H36: بيع | I36: سكر دوبل | J36: 150 | L36: ='02-04'!$K36+('02-04'!$J36/90) -> 1.6666667
H37: بيع | I37: علي اكشاي | K37: 54 | L37: ='02-04'!$K37+('02-04'!$J37/90) -> 54
H38: بيع | I38: موتير غسالة ستانلس | K38: 22 | L38: ='02-04'!$K38+('02-04'!$J38/90) -> 22
H39: بيع | I39: محمد الطير | K39: 105 | L39: ='02-04'!$K39+('02-04'!$J39/90) -> 105
H40: بيع | I40: براغي | J40: 510 | L40: ='02-04'!$K40+('02-04'!$J40/90) -> 5.6666667
H41: بيع | I41: موتير ليو حصان | K41: 63 | L41: ='02-04'!$K41+('02-04'!$J41/90) -> 63
...

Sheet 03-04
I1: حركة الصندوق | J1: =SUM(J3:J11) -> 285 | K1: =SUM(K3:K11) -> 165 | L1: =SUM(L3:L11) -> 168.16667
H2: العملية | I2: البيان | J2: اللبناني | K2: الدولار | L2: مبيع $
H3: بيع | K3: 100 | L3: =K3+(J3/90) -> 100
H4: بيع | J4: -225 | L4: =K4+(J4/90) -> -2.5
H5: بيع | K5: 15 | L5: =K5+(J5/90) -> 15
H6: بيع | J6: 100 | L6: =K6+(J6/90) -> 1.1111111
H7: بيع | J7: 360 | L7: =K7+(J7/90) -> 4
H8: بيع | K8: 10 | L8: =K8+(J8/90) -> 10
H9: بيع | J9: 50 | K9: 5 | L9: =K9+(J9/90) -> 5.5555556
H10: بيع | I10: مع الحاج | K10: 35 | L10: =K10+(J10/90) -> 35
L11: =K11+(J11/90) -> 0
A13: جرد اول النهار | I13: حركة الصندوق | J13: =SUM('03-04'!$J$15:$J$135) -> -70 | K13: =SUM('03-04'!$K$15:$K$135) -> -86 | L13: =SUM('03-04'!$L$15:$L$135) -> -86.777778 | N13: جرد اخر النهار
A14: الفئة دولار | B14: العدد | C14: المجموع | D14: الفئة لبناني | E14: العدد | F14: المجموع | H14: العملية | I14: البيان | J14: اللبناني | K14: الدولار | L14: مبيع $ | N14: الفئة دولار | O14: العدد | P14: المجموع | Q14: الفئة لبناني | R14: العدد | S14: المجموع
A15: 1 | C15: =A15*B15 -> 0 | D15: 5 | E15: 42 | F15: =D15*E15 -> 210 | H15: بيع | I15: مملوك | K15: 40 | L15: ='03-04'!$K15+('03-04'!$J15/90) -> 40 | N15: 1 | P15: =N15*O15 -> 0 | Q15: 5 | R15: 31 | S15: =Q15*R15 -> 155
A16: 5 | B16: 5 | C16: =A16*B16 -> 25 | D16: 10 | E16: 24 | F16: =D16*E16 -> 240 | H16: بيع | I16: باكس 18 | J16: 200 | K16: 25 | L16: ='03-04'!$K16+('03-04'!$J16/90) -> 27.222222 | N16: 5 | O16: 7 | P16: =N16*O16 -> 35 | Q16: 10 | R16: 24 | S16: =Q16*R16 -> 240
A17: 10 | B17: 55 | C17: =A17*B17 -> 550 | D17: 20 | E17: 2 | F17: =D17*E17 -> 40 | H17: بيع | I17: تنر | J17: 200 | L17: ='03-04'!$K17+('03-04'!$J17/90) -> 2.2222222 | N17: 10 | O17: 56 | P17: =N17*O17 -> 560 | Q17: 20 | R17: 3 | S17: =Q17*R17 -> 60
A18: 20 | B18: 16 | C18: =A18*B18 -> 320 | D18: 50 | E18: 5 | F18: =D18*E18 -> 250 | H18: بيع | I18: ابو حسن صالح | K18: 67 | L18: ='03-04'!$K18+('03-04'!$J18/90) -> 67 | N18: 20 | O18: 23 | P18: =N18*O18 -> 460 | Q18: 50 | R18: 2 | S18: =Q18*R18 -> 100
A19: 50 | B19: 3 | C19: =A19*B19 -> 150 | D19: 100 | E19: 15 | F19: =D19*E19 -> 1500 | H19: سحب | I19: من الحاج | K19: 10 | L19: ='03-04'!$K19+('03-04'!$J19/90) -> 10 | N19: 50 | O19: 6 | P19: =N19*O19 -> 300 | Q19: 100 | R19: 31 | S19: =Q19*R19 -> 3100
A20: 100 | B20: 1 | C20: =A20*B20 -> 100 | D20: المجموع | F20: =SUM(F15:F19) -> 2240 | H20: مصاريف | I20: بنزين | K20: -10 | L20: ='03-04'!$K20+('03-04'!$J20/90) -> -10 | N20: 100 | O20: 3 | P20: =N20*O20 -> 300 | Q20: المجموع | S20: =SUM(S15:S19) -> 3655
A21: المجموع | C21: =SUM(C15:C20) -> 1145 | H21: بيع | I21: خرطوشة فلتر | K21: 3 | L21: ='03-04'!$K21+('03-04'!$J21/90) -> 3 | N21: المجموع | P21: =SUM(P15:P20) -> 1655
H22: بيع | I22: اكياس ردم | J22: 270 | L22: ='03-04'!$K22+('03-04'!$J22/90) -> 3 | Q22: حركة الصندوق ل.ل | S22: =SUM('03-04'!$J$15:$J$135) -> -70
H23: بيع | I23: خلاط مجلى برم | J23: -180 | K23: 20 | L23: ='03-04'!$K23+('03-04'!$J23/90) -> 18 | N23: حركة الصندوق $ | P23: =SUM('03-04'!$K$15:$K$135) -> -86
H24: بيع | I24: ابو هشام | J24: -180 | K24: 50 | L24: ='03-04'!$K24+('03-04'!$J24/90) -> 48 | Q24: الفرق | S24: =S20-S22-F20 -> 1485
H25: بيع | I25: محمد فواز | J25: -300 | K25: 10 | L25: ='03-04'!$K25+('03-04'!$J25/90) -> 6.6666667 | N25: الفرق | P25: =P21-P23-C21 -> 596
H26: بيع | I26: عزقة 8ملم | J26: 25 | L26: ='03-04'!$K26+('03-04'!$J26/90) -> 0.27777778
H27: بيع | I27: قنينة 100 | J27: 400 | K27: 50 | L27: ='03-04'!$K27+('03-04'!$J27/90) -> 54.444444
H28: بيع | I28: قازان تيرمو | K28: 65 | L28: ='03-04'!$K28+('03-04'!$J28/90) -> 65
H29: بيع | I29: مع الحاج | K29: 57 | L29: ='03-04'!$K29+('03-04'!$J29/90) -> 57
H30: بيع | I30: مع الحاج | K30: 55 | L30: ='03-04'!$K30+('03-04'!$J30/90) -> 55
H31: سحب | I31: بيد الحاج | K31: -112 | L31: ='03-04'!$K31+('03-04'!$J31/90) -> -112
H32: بيع | I32: عثمان سوبره | K32: 80 | L32: ='03-04'!$K32+('03-04'!$J32/90) -> 80
H33: بيع | I33: عدة جنب وسكر | J33: 400 | K33: 20 | L33: ='03-04'!$K33+('03-04'!$J33/90) -> 24.444444
H34: بيع | I34: حنفية وعنق | J34: -180 | K34: 15 | L34: ='03-04'!$K34+('03-04'!$J34/90) -> 13
H35: بيع | I35: سبراي | J35: 150 | L35: ='03-04'!$K35+('03-04'!$J35/90) -> 1.6666667
H36: بيع | I36: مسكة دوش ونربيج | K36: 10 | L36: ='03-04'!$K36+('03-04'!$J36/90) -> 10
H37: بيع | I37: قطرون | J37: 170 | L37: ='03-04'!$K37+('03-04'!$J37/90) -> 1.8888889
H38: بيع | I38: اصبع بي يو | J38: -400 | K38: 10 | L38: ='03-04'!$K38+('03-04'!$J38/90) -> 5.5555556
H39: بيع | I39: حنفية غسالة | J39: -90 | K39: 5 | L39: ='03-04'!$K39+('03-04'!$J39/90) -> 4
H40: مصاريف | J40: -600 | L40: ='03-04'!$K40+('03-04'!$J40/90) -> -6.6666667
H41: بيع | I41: احمد حلمي | J41: 900 | L41: ='03-04'!$K41+('03-04'!$J41/90) -> 10
...

Sheet 04-04
I1: حركة الصندوق | J1: =SUM(J3:J11) -> -1180 | K1: =SUM(K3:K11) -> 14 | L1: =SUM(L3:L11) -> 0.88888889
H2: العملية | I2: البيان | J2: اللبناني | K2: الدولار | L2: مبيع $
H3: مصاريف | J3: -300 | L3: =K3+(J3/90) -> -3.3333333
H4: مصاريف | J4: -480 | L4: =K4+(J4/90) -> -5.3333333
H5: بيع | K5: 19 | L5: =K5+(J5/90) -> 19
H6: بيع | K6: 10 | L6: =K6+(J6/90) -> 10
H7: سحب | J7: -400 | L7: =K7+(J7/90) -> -4.4444444
H8: بيع | L8: =K8+(J8/90) -> 0
H9: بيع | K9: -15 | L9: =K9+(J9/90) -> -15
H10: بيع | L10: =K10+(J10/90) -> 0
L11: =K11+(J11/90) -> 0
A12: 03-04
A13: جرد اول النهار | I13: حركة الصندوق | J13: =SUM('04-04'!$J$15:$J$143) -> 935 | K13: =SUM('04-04'!$K$15:$K$143) -> 1047 | L13: =SUM('04-04'!$L$15:$L$143) -> 1057.3889 | N13: جرد اخر النهار
A14: الفئة دولار | B14: العدد | C14: المجموع | D14: الفئة لبناني | E14: العدد | F14: المجموع | H14: العملية | I14: البيان | J14: اللبناني | K14: الدولار | L14: مبيع $ | N14: الفئة دولار | O14: العدد | P14: المجموع | Q14: الفئة لبناني | R14: العدد | S14: المجموع
A15: 1 | B15: 3 | C15: =A15*B15 -> 3 | D15: 5 | E15: 26 | F15: =D15*E15 -> 130 | H15: بيع | I15: طابة | K15: 5 | L15: ='04-04'!$K15+('04-04'!$J15/90) -> 5 | N15: 1 | P15: =N15*O15 -> 0 | Q15: 5 | R15: 27 | S15: =Q15*R15 -> 135
A16: 5 | B16: 4 | C16: =A16*B16 -> 20 | D16: 10 | E16: 20 | F16: =D16*E16 -> 200 | H16: مصاريف | I16: كبايات وكلينكس | J16: -300 | L16: ='04-04'!$K16+('04-04'!$J16/90) -> -3.3333333 | N16: 5 | O16: 4 | P16: =N16*O16 -> 20 | Q16: 10 | R16: 12 | S16: =Q16*R16 -> 120
A17: 10 | B17: 55 | C17: =A17*B17 -> 550 | D17: 20 | E17: 3 | F17: =D17*E17 -> 60 | H17: بيع | J17: -315 | K17: 10 | L17: ='04-04'!$K17+('04-04'!$J17/90) -> 6.5 | N17: 10 | O17: 54 | P17: =N17*O17 -> 540 | Q17: 20 | R17: 1 | S17: =Q17*R17 -> 20
A18: 20 | B18: 20 | C18: =A18*B18 -> 400 | D18: 50 | F18: =D18*E18 -> 0 | H18: بيع | I18: مسكة سجب | J18: 320 | L18: ='04-04'!$K18+('04-04'!$J18/90) -> 3.5555556 | N18: 20 | O18: 39 | P18: =N18*O18 -> 780 | Q18: 50 | R18: 4 | S18: =Q18*R18 -> 200
A19: 50 | B19: 2 | C19: =A19*B19 -> 100 | D19: 100 | E19: 6 | F19: =D19*E19 -> 600 | H19: بيع | K19: 5 | L19: ='04-04'!$K19+('04-04'!$J19/90) -> 5 | N19: 50 | O19: 4 | P19: =N19*O19 -> 200 | Q19: 100 | R19: 10 | S19: =Q19*R19 -> 1000
A20: 100 | C20: =A20*B20 -> 0 | D20: المجموع | F20: =SUM(F15:F19) -> 990 | H20: بيع | K20: 2 | L20: ='04-04'!$K20+('04-04'!$J20/90) -> 2 | N20: 100 | O20: 6 | P20: =N20*O20 -> 600 | Q20: المجموع | S20: =SUM(S15:S19) -> 1475
A21: المجموع | C21: =SUM(C15:C20) -> 1073 | H21: بيع | I21: موتير حصام ليو | J21: 250 | K21: 60 | L21: ='04-04'!$K21+('04-04'!$J21/90) -> 62.777778 | N21: المجموع | P21: =SUM(P15:P20) -> 2140
D22: حركة الصندوق ل.ل | F22: {=INDIRECT("'"&$A$12&"'!J13")+J1} -> -1250 | H22: بيع | I22: مفتاح | J22: 150 | L22: ='04-04'!$K22+('04-04'!$J22/90) -> 1.6666667 | Q22: حركة الصندوق ل.ل | S22: =SUM('04-04'!$J$15:$J$143) -> 935
A23: حركة الصندوق $ | C23: {=INDIRECT("'"&$A$12&"'!K13")+K1} -> -72 | H23: بيع | I23: الديري | J23: -300 | K23: 60 | L23: ='04-04'!$K23+('04-04'!$J23/90) -> 56.666667 | N23: حركة الصندوق $ | P23: =SUM('04-04'!$K$15:$K$143) -> 1047
D24: الفرق | F24: {=F20-F22-INDIRECT("'"&$A$12&"'!f20")} -> 0 | H24: بيع | I24: احمد 3 | K24: 480 | L24: ='04-04'!$K24+('04-04'!$J24/90) -> 480 | Q24: الفرق | S24: =S20-S22-F20 -> -450
A25: الفرق | C25: {=C21-C23-INDIRECT("'"&$A$12&"'!c21")} -> 0 | H25: بيع | I25: تلزيق ورق | J25: 40 | L25: ='04-04'!$K25+('04-04'!$J25/90) -> 0.44444444 | N25: الفرق | P25: =P21-P23-C21 -> 20
H26: بيع | I26: مكنة لحام و تلحيم | K26: 45 | L26: ='04-04'!$K26+('04-04'!$J26/90) -> 45
H27: بيع | I27: شطافة | J27: 50 | K27: 5 | L27: ='04-04'!$K27+('04-04'!$J27/90) -> 5.5555556
H28: بيع | I28: ابو علي كبه | J28: 400 | K28: 390 | L28: ='04-04'!$K28+('04-04'!$J28/90) -> 394.44444
H29: بيع | I29: قفل | J29: 300 | L29: ='04-04'!$K29+('04-04'!$J29/90) -> 3.3333333
H30: بيع | I30: ابو خليل | K30: 90 | L30: ='04-04'!$K30+('04-04'!$J30/90) -> 90
H31: بيع | I31: جاهزة | J31: 550 | L31: ='04-04'!$K31+('04-04'!$J31/90) -> 6.1111111
H32: بيع | I32: حسين شري | J32: -90 | K32: 125 | L32: ='04-04'!$K32+('04-04'!$J32/90) -> 124
H33: بيع | I33: مجموعة دوش | K33: 5 | L33: ='04-04'!$K33+('04-04'!$J33/90) -> 5
H34: بيع | I34: موتير نص ليو | J34: -540 | K34: 40 | L34: ='04-04'!$K34+('04-04'!$J34/90) -> 34
H35: بيع | I35: مسكة خلاط | J35: 100 | L35: ='04-04'!$K35+('04-04'!$J35/90) -> 1.1111111
H36: سحب | I36: عدي | J36: -300 | L36: ='04-04'!$K36+('04-04'!$J36/90) -> -3.3333333
H37: بيع | I37: محمد قيسي | K37: 22 | L37: ='04-04'!$K37+('04-04'!$J37/90) -> 22
H38: سحب | I38: مع الحاج | K38: -22 | L38: ='04-04'!$K38+('04-04'!$J38/90) -> -22
H39: بيع | I39: حجر | J39: 150 | L39: ='04-04'!$K39+('04-04'!$J39/90) -> 1.6666667
H40: بيع | I40: تلحيم 40 | J40: 100 | K40: 10 | L40: ='04-04'!$K40+('04-04'!$J40/90) -> 11.111111
...

Sheet 05-04
I1: حركة الصندوق | J1: =SUM(J3:J11) -> 0 | K1: =SUM(K3:K11) -> 0 | L1: =SUM(L3:L11) -> 0
H2: العملية | I2: البيان | J2: اللبناني | K2: الدولار | L2: مبيع $
H3: بيع | L3: =K3+(J3/90) -> 0
H4: بيع | L4: =K4+(J4/90) -> 0
H5: بيع | L5: =K5+(J5/90) -> 0
H6: بيع | L6: =K6+(J6/90) -> 0
H7: بيع | L7: =K7+(J7/90) -> 0
H8: بيع | L8: =K8+(J8/90) -> 0
H9: بيع | L9: =K9+(J9/90) -> 0
H10: بيع | L10: =K10+(J10/90) -> 0
L11: =K11+(J11/90) -> 0
A12: 04-04
A13: جرد اول النهار | I13: حركة الصندوق | J13: =SUM('05-04'!$J$15:$J$30) -> 0 | K13: =SUM('05-04'!$K$15:$K$30) -> 0 | L13: =SUM('05-04'!$L$15:$L$30) -> 0 | N13: جرد اخر النهار
A14: الفئة دولار | B14: العدد | C14: المجموع | D14: الفئة لبناني | E14: العدد | F14: المجموع | H14: العملية | I14: البيان | J14: اللبناني | K14: الدولار | L14: مبيع $ | N14: الفئة دولار | O14: العدد | P14: المجموع | Q14: الفئة لبناني | R14: العدد | S14: المجموع
A15: 1 | C15: =A15*B15 -> 0 | D15: 5 | F15: =D15*E15 -> 0 | H15: بيع | I15: مع الحاج | K15: 2000 | L15: ='05-04'!$K15+('05-04'!$J15/90) -> 2000 | N15: 1 | P15: =N15*O15 -> 0 | Q15: 5 | S15: =Q15*R15 -> 0
A16: 5 | C16: =A16*B16 -> 0 | D16: 10 | F16: =D16*E16 -> 0 | H16: سحب | I16: مع الحاج | K16: -2000 | L16: ='05-04'!$K16+('05-04'!$J16/90) -> -2000 | N16: 5 | P16: =N16*O16 -> 0 | Q16: 10 | S16: =Q16*R16 -> 0
A17: 10 | C17: =A17*B17 -> 0 | D17: 20 | F17: =D17*E17 -> 0 | H17: بيع | L17: ='05-04'!$K17+('05-04'!$J17/90) -> 0 | N17: 10 | P17: =N17*O17 -> 0 | Q17: 20 | S17: =Q17*R17 -> 0
A18: 20 | C18: =A18*B18 -> 0 | D18: 50 | F18: =D18*E18 -> 0 | H18: بيع | L18: ='05-04'!$K18+('05-04'!$J18/90) -> 0 | N18: 20 | P18: =N18*O18 -> 0 | Q18: 50 | S18: =Q18*R18 -> 0
A19: 50 | C19: =A19*B19 -> 0 | D19: 100 | F19: =D19*E19 -> 0 | H19: بيع | L19: ='05-04'!$K19+('05-04'!$J19/90) -> 0 | N19: 50 | P19: =N19*O19 -> 0 | Q19: 100 | S19: =Q19*R19 -> 0
A20: 100 | C20: =A20*B20 -> 0 | D20: المجموع | F20: =SUM(F15:F19) -> 0 | H20: بيع | L20: ='05-04'!$K20+('05-04'!$J20/90) -> 0 | N20: 100 | P20: =N20*O20 -> 0 | Q20: المجموع | S20: =SUM(S15:S19) -> 0
A21: المجموع | C21: =SUM(C15:C20) -> 0 | H21: بيع | L21: ='05-04'!$K21+('05-04'!$J21/90) -> 0 | N21: المجموع | P21: =SUM(P15:P20) -> 0
D22: حركة الصندوق ل.ل | F22: {=INDIRECT("'"&$A$12&"'!J13")+J1} -> 935 | H22: بيع | L22: ='05-04'!$K22+('05-04'!$J22/90) -> 0 | Q22: حركة الصندوق ل.ل | S22: =SUM('05-04'!$J$15:$J$30) -> 0
A23: حركة الصندوق $ | C23: {=INDIRECT("'"&$A$12&"'!K13")+K1} -> 1047 | H23: بيع | L23: ='05-04'!$K23+('05-04'!$J23/90) -> 0 | N23: حركة الصندوق $ | P23: =SUM('05-04'!$K$15:$K$30) -> 0
D24: الفرق | F24: {=F20-F22-INDIRECT("'"&$A$12&"'!f20")} -> -1925 | H24: بيع | L24: ='05-04'!$K24+('05-04'!$J24/90) -> 0 | Q24: الفرق | S24: =S20-S22-F20 -> 0
A25: الفرق | C25: {=C21-C23-INDIRECT("'"&$A$12&"'!c21")} -> -2120 | H25: بيع | L25: ='05-04'!$K25+('05-04'!$J25/90) -> 0 | N25: الفرق | P25: =P21-P23-C21 -> 0
H26: بيع | L26: ='05-04'!$K26+('05-04'!$J26/90) -> 0
H27: بيع | L27: ='05-04'!$K27+('05-04'!$J27/90) -> 0
H28: بيع | L28: ='05-04'!$K28+('05-04'!$J28/90) -> 0
H29: بيع | L29: ='05-04'!$K29+('05-04'!$J29/90) -> 0
H30: بيع | L30: ='05-04'!$K30+('05-04'!$J30/90) -> 0

Sheet 06-04
I1: حركة الصندوق | J1: =SUM(J3:J15) -> 1245 | K1: =SUM(K3:K15) -> 141 | L1: =SUM(L3:L15) -> 154.83333
H2: العملية | I2: البيان | J2: اللبناني | K2: الدولار | L2: مبيع $
H3: بيع | J3: 145 | L3: =K3+(J3/90) -> 1.6111111
H4: بيع | K4: 10 | L4: =K4+(J4/90) -> 10
H5: بيع | J5: 180 | L5: =K5+(J5/90) -> 2
H6: بيع | J6: 100 | L6: =K6+(J6/90) -> 1.1111111
H7: بيع | K7: 5 | L7: =K7+(J7/90) -> 5
H8: بيع | J8: 250 | L8: =K8+(J8/90) -> 2.7777778
H9: بيع | J9: 400 | L9: =K9+(J9/90) -> 4.4444444
H10: بيع | J10: 450 | K10: 20 | L10: =K10+(J10/90) -> 25
H11: بيع | K11: 22 | L11: =K11+(J11/90) -> 22
H12: بيع | K12: 84 | L12: =K12+(J12/90) -> 84
H13: بيع | J13: 80 | L13: =K13+(J13/90) -> 0.88888889
H14: بيع | I14: مطابقة | J14: -360 | L14: =K14+(J14/90) -> -4
H15: بيع | L15: =K15+(J15/90) -> 0
A16: 04-04
A17: جرد اول النهار | I17: حركة الصندوق | J17: =SUM('06-04'!$J$19:$J$129) -> 10765 | K17: =SUM('06-04'!$K$19:$K$129) -> 1413 | L17: =SUM('06-04'!$L$19:$L$129) -> 1532.6111 | N17: جرد اخر النهار
A18: الفئة دولار | B18: العدد | C18: المجموع | D18: الفئة لبناني | E18: العدد | F18: المجموع | H18: العملية | I18: البيان | J18: اللبناني | K18: الدولار | L18: مبيع $ | N18: الفئة دولار | O18: العدد | P18: المجموع | Q18: الفئة لبناني | R18: العدد | S18: المجموع
A19: 1 | B19: 1 | C19: =A19*B19 -> 1 | D19: 5 | E19: 28 | F19: =D19*E19 -> 140 | H19: بيع | I19: مسكة شطافة | J19: -150 | K19: 5 | L19: ='06-04'!$K19+('06-04'!$J19/90) -> 3.3333333 | N19: 1 | O19: 9 | P19: =N19*O19 -> 9 | Q19: 5 | S19: =Q19*R19 -> 0
A20: 5 | B20: 2 | C20: =A20*B20 -> 10 | D20: 10 | E20: 13 | F20: =D20*E20 -> 130 | H20: بيع | I20: مع ابراهيم 3m بيروت | J20: -180 | K20: -25 | L20: ='06-04'!$K20+('06-04'!$J20/90) -> -27 | N20: 5 | O20: 1 | P20: =N20*O20 -> 5 | Q20: 10 | S20: =Q20*R20 -> 0
A21: 10 | B21: 53 | C21: =A21*B21 -> 530 | D21: 20 | E21: 0 | F21: =D21*E21 -> 0 | H21: سحب | I21: - | K21: -40 | L21: ='06-04'!$K21+('06-04'!$J21/90) -> -40 | N21: 10 | O21: 28 | P21: =N21*O21 -> 280 | Q21: 20 | S21: =Q21*R21 -> 0
A22: 20 | B22: 41 | C22: =A22*B22 -> 820 | D22: 50 | E22: 4 | F22: =D22*E22 -> 200 | H22: بيع | I22: - | K22: 31 | L22: ='06-04'!$K22+('06-04'!$J22/90) -> 31 | N22: 20 | O22: 30 | P22: =N22*O22 -> 600 | Q22: 50 | R22: 1 | S22: =Q22*R22 -> 50
A23: 50 | B23: 4 | C23: =A23*B23 -> 200 | D23: 100 | E23: 27 | F23: =D23*E23 -> 2700 | H23: مصاريف | I23: بنزين عبد | J23: -300 | L23: ='06-04'!$K23+('06-04'!$J23/90) -> -3.3333333 | N23: 50 | O23: 1 | P23: =N23*O23 -> 50 | Q23: 100 | R23: 1 | S23: =Q23*R23 -> 100
A24: 100 | B24: 7 | C24: =A24*B24 -> 700 | D24: المجموع | F24: =SUM(F19:F23) -> 3170 | H24: بيع | I24: احمد عباس | K24: 120 | L24: ='06-04'!$K24+('06-04'!$J24/90) -> 120 | N24: 100 | O24: 1 | P24: =N24*O24 -> 100 | Q24: المجموع | S24: =SUM(S19:S23) -> 150
A25: المجموع | C25: =SUM(C19:C24) -> 2261 | H25: بيع | I25: نربيج غسالة | J25: 300 | L25: ='06-04'!$K25+('06-04'!$J25/90) -> 3.3333333 | N25: المجموع | P25: =SUM(P19:P24) -> 1044
B26: 0 | D26: حركة الصندوق ل.ل | F26: {=INDIRECT("'"&$A$16&"'!J13")+J1} -> 2180 | H26: بيع | I26: 3m بيروت | K26: 50 | L26: ='06-04'!$K26+('06-04'!$J26/90) -> 50 | Q26: حركة الصندوق ل.ل | S26: =SUM('06-04'!$J$19:$J$129) -> 10765
A27: حركة الصندوق $ | C27: {=INDIRECT("'"&$A$16&"'!K13")+K1} -> 1188 | H27: بيع | I27: بنزين ابراهيم | J27: -300 | L27: ='06-04'!$K27+('06-04'!$J27/90) -> -3.3333333 | N27: حركة الصندوق $ | P27: =SUM('06-04'!$K$19:$K$129) -> 1413
D28: الفرق | F28: {=F24-F26-INDIRECT("'"&$A$16&"'!f20")} -> 0 | H28: بيع | I28: - | J28: -100 | K28: 5 | L28: ='06-04'!$K28+('06-04'!$J28/90) -> 3.8888889 | Q28: الفرق | S28: =S24-S26-F24 -> -13785
A29: الفرق | C29: {=C25-C27-INDIRECT("'"&$A$16&"'!c21")} -> 0 | H29: بيع | I29: موتير | K29: 48 | L29: ='06-04'!$K29+('06-04'!$J29/90) -> 48 | N29: الفرق | P29: =P25-P27-C25 -> -2630
H30: بيع | I30: مسكة شطافة | J30: 100 | L30: ='06-04'!$K30+('06-04'!$J30/90) -> 1.1111111
H31: بيع | I31: مفصلات | J31: 100 | L31: ='06-04'!$K31+('06-04'!$J31/90) -> 1.1111111
H32: بيع | I32: قلب طويل | J32: 270 | L32: ='06-04'!$K32+('06-04'!$J32/90) -> 3
H33: بيع | I33: ايزي وجوان | J33: 340 | L33: ='06-04'!$K33+('06-04'!$J33/90) -> 3.7777778
H34: بيع | I34: اصبع سيليكون | J34: 360 | L34: ='06-04'!$K34+('06-04'!$J34/90) -> 4
H35: بيع | I35: للحاج | K35: 192 | L35: ='06-04'!$K35+('06-04'!$J35/90) -> 192
H36: سحب | I36: للحاج | K36: -192 | L36: ='06-04'!$K36+('06-04'!$J36/90) -> -192
H37: بيع | I37: محمود مملوك | J37: -100 | K37: 65 | L37: ='06-04'!$K37+('06-04'!$J37/90) -> 63.888889
H38: بيع | I38: ابو طارق | K38: 30 | L38: ='06-04'!$K38+('06-04'!$J38/90) -> 30
H39: بيع | I39: حديد وتلحيم | J39: -270 | K39: -20 | L39: ='06-04'!$K39+('06-04'!$J39/90) -> -23
H40: بيع | I40: كاتو | J40: 200 | L40: ='06-04'!$K40+('06-04'!$J40/90) -> 2.2222222
...

Sheet 07-04
I1: حركة الصندوق | J1: =SUM(J3:J18) -> -7720 | K1: =SUM(K3:K18) -> -2625 | L1: =SUM(L3:L18) -> -2710.7778
H2: العملية | I2: البيان | J2: اللبناني | K2: الدولار | L2: مبيع $
H3: سحب | J3: -10000 | K3: -2700 | L3: =K3+(J3/90) -> -2811.1111
H4: بيع | K4: 1 | L4: =K4+(J4/90) -> 1
H5: بيع | J5: 220 | L5: =K5+(J5/90) -> 2.4444444
H6: بيع | J6: 600 | L6: =K6+(J6/90) -> 6.6666667
H7: بيع | J7: 70 | L7: =K7+(J7/90) -> 0.77777778
H8: بيع | K8: 30 | L8: =K8+(J8/90) -> 30
H9: بيع | K9: 4 | L9: =K9+(J9/90) -> 4
H10: بيع | K10: 10 | L10: =K10+(J10/90) -> 10
H11: بيع | J11: -350 | L11: =K11+(J11/90) -> -3.8888889
H12: بيع | J12: 50 | L12: =K12+(J12/90) -> 0.55555556
H13: بيع | K13: 30 | L13: =K13+(J13/90) -> 30
H14: بيع | J14: -350 | L14: =K14+(J14/90) -> -3.8888889
H15: بيع | J15: 300 | L15: =K15+(J15/90) -> 3.3333333
H16: بيع | J16: 600 | L16: =K16+(J16/90) -> 6.6666667
H17: بيع | I17: مطابقة | J17: 1140 | L17: =K17+(J17/90) -> 12.666667
A18: رصيد قديم من تاريخ | H18: بيع | L18: =K18+(J18/90) -> 0
A19: 06-04
A20: جرد اول النهار | I20: حركة الصندوق | J20: =SUM('07-04'!$J$22:$J$126) -> 1375 | K20: =SUM('07-04'!$K$22:$K$126) -> 5820 | L20: =SUM('07-04'!$L$22:$L$126) -> 5835.2778 | N20: جرد اخر النهار
A21: الفئة دولار | B21: العدد | C21: المجموع | D21: الفئة لبناني | E21: العدد | F21: المجموع | H21: العملية | I21: البيان | J21: اللبناني | K21: الدولار | L21: مبيع $ | N21: الفئة دولار | O21: العدد | P21: المجموع | Q21: الفئة لبناني | R21: العدد | S21: المجموع
A22: 1 | B22: 9 | C22: =A22*B22 -> 9 | D22: 5 | E22: 31 | F22: =D22*E22 -> 155 | H22: بيع | J22: 300 | L22: ='07-04'!$K22+('07-04'!$J22/90) -> 3.3333333 | N22: 1 | O22: 15 | P22: =N22*O22 -> 15 | Q22: 5 | R22: 36 | S22: =Q22*R22 -> 180
A23: 5 | B23: 6 | C23: =A23*B23 -> 30 | D23: 10 | E23: 18 | F23: =D23*E23 -> 180 | H23: بيع | I23: ترابة سريعة | J23: -850 | K23: 20 | L23: ='07-04'!$K23+('07-04'!$J23/90) -> 10.555556 | N23: 5 | O23: 0 | P23: =N23*O23 -> 0 | Q23: 10 | R23: 22 | S23: =Q23*R23 -> 220
A24: 10 | B24: 38 | C24: =A24*B24 -> 380 | D24: 20 | E24: 24 | F24: =D24*E24 -> 480 | H24: بيع | I24: اتوماتيك | K24: 35 | L24: ='07-04'!$K24+('07-04'!$J24/90) -> 35 | N24: 10 | O24: 24 | P24: =N24*O24 -> 240 | Q24: 20 | R24: 22 | S24: =Q24*R24 -> 440
A25: 20 | B25: 29 | C25: =A25*B25 -> 580 | D25: 50 | E25: 10 | F25: =D25*E25 -> 500 | H25: بيع | I25: ايزي وصباب ايطالي | J25: 360 | L25: ='07-04'!$K25+('07-04'!$J25/90) -> 4 | N25: 20 | O25: 27 | P25: =N25*O25 -> 540 | Q25: 50 | R25: 11 | S25: =Q25*R25 -> 550
A26: 50 | B26: 1 | C26: =A26*B26 -> 50 | D26: 100 | E26: 49 | F26: =D26*E26 -> 4900 | H26: بيع | I26: سليم بواب | K26: 825 | L26: ='07-04'!$K26+('07-04'!$J26/90) -> 825 | N26: 50 | O26: 9 | P26: =N26*O26 -> 450 | Q26: 100 | R26: 62 | S26: =Q26*R26 -> 6200
A27: 100 | C27: =A27*B27 -> 0 | D27: المجموع | F27: =SUM(F22:F26) -> 6215 | H27: سحب | I27: للحاج | K27: -825 | L27: ='07-04'!$K27+('07-04'!$J27/90) -> -825 | N27: 100 | O27: 56 | P27: =N27*O27 -> 5600 | Q27: المجموع | S27: =SUM(S22:S26) -> 7590
A28: المجموع | C28: =SUM(C22:C27) -> 1049 | H28: بيع | I28: رياض | K28: 75 | L28: ='07-04'!$K28+('07-04'!$J28/90) -> 75 | N28: المجموع | P28: =SUM(P22:P27) -> 6845
B29: 0 | D29: حركة الصندوق ل.ل | F29: {=INDIRECT("'"&$A$19&"'!J17")+J1} -> 3045 | H29: بيع | I29: فاتورة | K29: 119 | L29: ='07-04'!$K29+('07-04'!$J29/90) -> 119 | Q29: حركة الصندوق ل.ل | S29: =SUM('07-04'!$J$22:$J$126) -> 1375
A30: حركة الصندوق $ | C30: {=INDIRECT("'"&$A$19&"'!K17")+K1} -> -1212 | H30: بيع | I30: ترابة سوداء | J30: 100 | L30: ='07-04'!$K30+('07-04'!$J30/90) -> 1.1111111 | N30: حركة الصندوق $ | P30: =SUM('07-04'!$K$22:$K$126) -> 5820
D31: الفرق | F31: {=F27-F29-INDIRECT("'"&$A$19&"'!f24")} -> 0 | H31: بيع | I31: مخالفة دوش | K31: 1 | L31: ='07-04'!$K31+('07-04'!$J31/90) -> 1 | Q31: الفرق | S31: =S27-S29-F27 -> 0
A32: الفرق | C32: {=C28-C30-INDIRECT("'"&$A$19&"'!c25")} -> 0 | H32: بيع | I32: ايزي وصباب | K32: 4 | L32: ='07-04'!$K32+('07-04'!$J32/90) -> 4 | N32: الفرق | P32: =P28-P30-C28 -> -24
H33: بيع | I33: وصل | K33: 1 | L33: ='07-04'!$K33+('07-04'!$J33/90) -> 1
H34: بيع | I34: وصل | J34: 100 | L34: ='07-04'!$K34+('07-04'!$J34/90) -> 1.1111111
H35: بيع | I35: رزيستنس | J35: 50 | K35: 11 | L35: ='07-04'!$K35+('07-04'!$J35/90) -> 11.555556
H36: بيع | I36: ترابة بيضاء | J36: 35 | L36: ='07-04'!$K36+('07-04'!$J36/90) -> 0.38888889
H37: بيع | I37: طابة جنب | K37: 21 | L37: ='07-04'!$K37+('07-04'!$J37/90) -> 21
H38: بيع | I38: تلزيق المنيوم | J38: 200 | L38: ='07-04'!$K38+('07-04'!$J38/90) -> 2.2222222
H39: بيع | I39: زريق | K39: 100 | L39: ='07-04'!$K39+('07-04'!$J39/90) -> 100
H40: بيع | I40: مشحاف | J40: 70 | L40: ='07-04'!$K40+('07-04'!$J40/90) -> 0.77777778
...

Sheet 08-04
I1: حركة الصندوق | J1: =SUM(J3:J18) -> -520 | K1: =SUM(K3:K18) -> 270 | L1: =SUM(L3:L18) -> 264.22222
H2: العملية | I2: البيان | J2: اللبناني | K2: الدولار | L2: مبيع $
H3: بيع | K3: 60 | L3: =K3+(J3/90) -> 60
H4: بيع | J4: 180 | L4: =K4+(J4/90) -> 2
H5: بيع | J5: -700 | K5: 10 | L5: =K5+(J5/90) -> 2.2222222
H6: بيع | K6: 100 | L6: =K6+(J6/90) -> 100
H7: بيع | K7: 100 | L7: =K7+(J7/90) -> 100
H8: بيع | L8: =K8+(J8/90) -> 0
H9: بيع | L9: =K9+(J9/90) -> 0
H10: بيع | L10: =K10+(J10/90) -> 0
H11: بيع | L11: =K11+(J11/90) -> 0
H12: بيع | L12: =K12+(J12/90) -> 0
H13: بيع | L13: =K13+(J13/90) -> 0
H14: بيع | L14: =K14+(J14/90) -> 0
H15: بيع | L15: =K15+(J15/90) -> 0
H16: بيع | L16: =K16+(J16/90) -> 0
H17: بيع | L17: =K17+(J17/90) -> 0
A18: رصيد قديم من تاريخ | H18: بيع | L18: =K18+(J18/90) -> 0
A19: 07-04
A20: جرد اول النهار | I20: حركة الصندوق | J20: =SUM('08-04'!$J$22:$J$76) -> -65 | K20: =SUM('08-04'!$K$22:$K$76) -> -6391 | L20: =SUM('08-04'!$L$22:$L$76) -> -6391.7222 | N20: جرد اخر النهار
A21: الفئة دولار | B21: العدد | C21: المجموع | D21: الفئة لبناني | E21: العدد | F21: المجموع | H21: العملية | I21: البيان | J21: اللبناني | K21: الدولار | L21: مبيع $ | N21: الفئة دولار | O21: العدد | P21: المجموع | Q21: الفئة لبناني | R21: العدد | S21: المجموع
A22: 1 | B22: 9 | C22: =A22*B22 -> 9 | D22: 5 | E22: 36 | F22: =D22*E22 -> 180 | H22: بيع | I22: قلب ومسكة ايطالي 3 | J22: -650 | K22: 20 | L22: ='08-04'!$K22+('08-04'!$J22/90) -> 12.777778 | N22: 1 | O22: 11 | P22: =N22*O22 -> 11 | Q22: 5 | R22: 35 | S22: =Q22*R22 -> 175
A23: 5 | C23: =A23*B23 -> 0 | D23: 10 | E23: 20 | F23: =D23*E23 -> 200 | H23: بيع | I23: سدة | J23: 220 | L23: ='08-04'!$K23+('08-04'!$J23/90) -> 2.4444444 | N23: 5 | O23: 1 | P23: =N23*O23 -> 5 | Q23: 10 | R23: 18 | S23: =Q23*R23 -> 180
A24: 10 | B24: 21 | C24: =A24*B24 -> 210 | D24: 20 | E24: 22 | F24: =D24*E24 -> 440 | H24: بيع | I24: سكر دوبل | J24: 90 | K24: 2 | L24: ='08-04'!$K24+('08-04'!$J24/90) -> 3 | N24: 10 | O24: 24 | P24: =N24*O24 -> 240 | Q24: 20 | R24: 20 | S24: =Q24*R24 -> 400
A25: 20 | B25: 26 | C25: =A25*B25 -> 520 | D25: 50 | E25: 11 | F25: =D25*E25 -> 550 | H25: بيع | I25: قوى الامن | J25: 44400 | L25: ='08-04'!$K25+('08-04'!$J25/90) -> 493.33333 | N25: 20 | O25: 25 | P25: =N25*O25 -> 500 | Q25: 50 | R25: 5 | S25: =Q25*R25 -> 250
A26: 50 | B26: 8 | C26: =A26*B26 -> 400 | D26: 100 | E26: 57 | F26: =D26*E26 -> 5700 | H26: سحب | I26: بالخزنة | J26: -44400 | L26: ='08-04'!$K26+('08-04'!$J26/90) -> -493.33333 | N26: 50 | O26: 9 | P26: =N26*O26 -> 450 | Q26: 100 | R26: 62 | S26: =Q26*R26 -> 6200
A27: 100 | B27: 60 | C27: =A27*B27 -> 6000 | D27: المجموع | F27: =SUM(F22:F26) -> 7070 | H27: بيع | I27: مجراية | K27: 20 | L27: ='08-04'!$K27+('08-04'!$J27/90) -> 20 | N27: 100 | O27: 11 | P27: =N27*O27 -> 1100 | Q27: المجموع | S27: =SUM(S22:S26) -> 7205
A28: المجموع | C28: =SUM(C22:C27) -> 7139 | H28: بيع | I28: كوع + تلزيق | K28: 4 | L28: ='08-04'!$K28+('08-04'!$J28/90) -> 4 | N28: المجموع | P28: =SUM(P22:P27) -> 2306
B29: 0 | D29: حركة الصندوق ل.ل | F29: {=INDIRECT("'"&$A$19&"'!J20")+J1} -> 855 | H29: بيع | I29: تركية | K29: 365 | L29: ='08-04'!$K29+('08-04'!$J29/90) -> 365 | Q29: حركة الصندوق ل.ل | S29: =SUM('08-04'!$J$22:$J$76) -> -65
A30: حركة الصندوق $ | C30: {=INDIRECT("'"&$A$19&"'!K20")+K1} -> 6090 | H30: بيع | I30: ابو موسى | K30: 400 | L30: ='08-04'!$K30+('08-04'!$J30/90) -> 400 | N30: حركة الصندوق $ | P30: =SUM('08-04'!$K$22:$K$76) -> -6391
D31: الفرق | F31: {=F27-F29-INDIRECT("'"&$A$19&"'!f27")} -> 0 | H31: بيع | I31: بلال | K31: 170 | L31: ='08-04'!$K31+('08-04'!$J31/90) -> 170 | Q31: الفرق | S31: =S27-S29-F27 -> 200
A32: الفرق | C32: {=C28-C30-INDIRECT("'"&$A$19&"'!c28")} -> 0 | H32: سحب | I32: للحاج فواتير نقدية | K32: -935 | L32: ='08-04'!$K32+('08-04'!$J32/90) -> -935 | N32: الفرق | P32: =P28-P30-C28 -> 1558
H33: سحب | I33: من الحاج | J33: 2000 | L33: ='08-04'!$K33+('08-04'!$J33/90) -> 22.222222
H34: مصاريف | I34: بنزين ابو هيثم | J34: -2000 | L34: ='08-04'!$K34+('08-04'!$J34/90) -> -22.222222
H35: بيع | I35: لفة | J35: -135 | K35: 10 | L35: ='08-04'!$K35+('08-04'!$J35/90) -> 8.5
H36: بيع | I36: ترابة بيضاء | J36: 60 | L36: ='08-04'!$K36+('08-04'!$J36/90) -> 0.66666667
H37: بيع | I37: تلزيق بلاط وترابة | J37: 280 | K37: 10 | L37: ='08-04'!$K37+('08-04'!$J37/90) -> 13.111111
H38: بيع | I38: ترابة | J38: 30 | L38: ='08-04'!$K38+('08-04'!$J38/90) -> 0.33333333
H39: بيع | I39: جهاد الاغا | K39: 10 | L39: ='08-04'!$K39+('08-04'!$J39/90) -> 10
H40: سحب | I40: بالخزنة | K40: -6000 | L40: ='08-04'!$K40+('08-04'!$J40/90) -> -6000
...

Sheet 09-04
I1: حركة الصندوق | J1: =SUM(J3:J18) -> 880 | K1: =SUM(K3:K18) -> 390 | L1: =SUM(L3:L18) -> 399.77778
H2: العملية | I2: البيان | J2: اللبناني | K2: الدولار | L2: مبيع $
H3: بيع | J3: -50 | K3: 20 | L3: =K3+(J3/90) -> 19.444444
H4: بيع | J4: 990 | L4: =K4+(J4/90) -> 11
H5: بيع | J5: 180 | L5: =K5+(J5/90) -> 2
H6: بيع | J6: 350 | L6: =K6+(J6/90) -> 3.8888889
H7: بيع | J7: 180 | L7: =K7+(J7/90) -> 2
H8: بيع | K8: 5 | L8: =K8+(J8/90) -> 5
H9: بيع | J9: -270 | L9: =K9+(J9/90) -> -3
H10: بيع | K10: 65 | L10: =K10+(J10/90) -> 65
H11: بيع | K11: 110 | L11: =K11+(J11/90) -> 110
H12: بيع | J12: 200 | L12: =K12+(J12/90) -> 2.2222222
H13: بيع | J13: 200 | L13: =K13+(J13/90) -> 2.2222222
H14: بيع | K14: -10 | L14: =K14+(J14/90) -> -10
H15: بيع | J15: -900 | K15: 200 | L15: =K15+(J15/90) -> 190
H16: بيع | L16: =K16+(J16/90) -> 0
H17: بيع | L17: =K17+(J17/90) -> 0
A18: رصيد قديم من تاريخ | H18: بيع | L18: =K18+(J18/90) -> 0
A19: 08-04
A20: جرد اول النهار | I20: حركة الصندوق | J20: =SUM('09-04'!$J$22:$J$110) -> -1290 | K20: =SUM('09-04'!$K$22:$K$110) -> -94 | L20: =SUM('09-04'!$L$22:$L$110) -> -108.33333 | N20: جرد اخر النهار
A21: الفئة دولار | B21: العدد | C21: المجموع | D21: الفئة لبناني | E21: العدد | F21: المجموع | H21: العملية | I21: البيان | J21: اللبناني | K21: الدولار | L21: مبيع $ | N21: الفئة دولار | O21: العدد | P21: المجموع | Q21: الفئة لبناني | R21: العدد | S21: المجموع
A22: 1 | B22: 8 | C22: =A22*B22 -> 8 | D22: 5 | E22: 37 | F22: =D22*E22 -> 185 | H22: بيع | I22: صرف | J22: -900 | K22: 10 | L22: ='09-04'!$K22+('09-04'!$J22/90) -> 0 | N22: 1 | O22: 7 | P22: =N22*O22 -> 7 | Q22: 5 | R22: 34 | S22: =Q22*R22 -> 170
A23: 5 | B23: 2 | C23: =A23*B23 -> 10 | D23: 10 | E23: 20 | F23: =D23*E23 -> 200 | H23: بيع | I23: ابو مهدي | J23: -225 | K23: 20 | L23: ='09-04'!$K23+('09-04'!$J23/90) -> 17.5 | N23: 5 | O23: 2 | P23: =N23*O23 -> 10 | Q23: 10 | R23: 19 | S23: =Q23*R23 -> 190
A24: 10 | B24: 23 | C24: =A24*B24 -> 230 | D24: 20 | E24: 20 | F24: =D24*E24 -> 400 | H24: بيع | I24: فاتورة | J24: 940 | L24: ='09-04'!$K24+('09-04'!$J24/90) -> 10.444444 | N24: 10 | O24: 27 | P24: =N24*O24 -> 270 | Q24: 20 | R24: 26 | S24: =Q24*R24 -> 520
A25: 20 | B25: 22 | C25: =A25*B25 -> 440 | D25: 50 | E25: 2 | F25: =D25*E25 -> 100 | H25: مصاريف | I25: بنزين عبد | J25: -300 | L25: ='09-04'!$K25+('09-04'!$J25/90) -> -3.3333333 | N25: 20 | O25: 24 | P25: =N25*O25 -> 480 | Q25: 50 | R25: 1 | S25: =Q25*R25 -> 50
A26: 50 | B26: 1 | C26: =A26*B26 -> 50 | D26: 100 | E26: 70 | F26: =D26*E26 -> 7000 | H26: بيع | I26: جميل ترجمان | J26: 18100 | L26: ='09-04'!$K26+('09-04'!$J26/90) -> 201.11111 | N26: 50 | O26: 7 | P26: =N26*O26 -> 350 | Q26: 100 | R26: 66 | S26: =Q26*R26 -> 6600
A27: 100 | B27: 4 | C27: =A27*B27 -> 400 | D27: المجموع | F27: =SUM(F22:F26) -> 7885 | H27: بيع | I27: احمد 3 | J27: 400 | K27: 5 | L27: ='09-04'!$K27+('09-04'!$J27/90) -> 9.4444444 | N27: 100 | O27: 18 | P27: =N27*O27 -> 1800 | Q27: المجموع | S27: =SUM(S22:S26) -> 7530
A28: المجموع | C28: =SUM(C22:C27) -> 1138 | H28: بيع | J28: 75 | L28: ='09-04'!$K28+('09-04'!$J28/90) -> 0.83333333 | N28: المجموع | P28: =SUM(P22:P27) -> 2917
B29: 0 | D29: حركة الصندوق ل.ل | F29: {=INDIRECT("'"&$A$19&"'!J20")+J1} -> 815 | H29: سحب | I29: بالخزنة | J29: -20000 | L29: ='09-04'!$K29+('09-04'!$J29/90) -> -222.22222 | Q29: حركة الصندوق ل.ل | S29: =SUM('09-04'!$J$22:$J$110) -> -1290
A30: حركة الصندوق $ | C30: {=INDIRECT("'"&$A$19&"'!K20")+K1} -> -6001 | H30: بيع | I30: قطع وصل | J30: 200 | L30: ='09-04'!$K30+('09-04'!$J30/90) -> 2.2222222 | N30: حركة الصندوق $ | P30: =SUM('09-04'!$K$22:$K$110) -> -94
D31: الفرق | F31: {=F27-F29-INDIRECT("'"&$A$19&"'!f27")} -> 0 | H31: بيع | I31: ابو هادي | K31: 10 | L31: ='09-04'!$K31+('09-04'!$J31/90) -> 10 | Q31: الفرق | S31: =S27-S29-F27 -> 935
A32: الفرق | C32: {=C28-C30-INDIRECT("'"&$A$19&"'!c28")} -> 0 | H32: بيع | I32: ابو هادي | J32: -180 | K32: 10 | L32: ='09-04'!$K32+('09-04'!$J32/90) -> 8 | N32: الفرق | P32: =P28-P30-C28 -> 1873
H33: بيع | I33: علي ايبو | K33: 90 | L33: ='09-04'!$K33+('09-04'!$J33/90) -> 90
H34: بيع | I34: ورق حف | J34: 50 | K34: 10 | L34: ='09-04'!$K34+('09-04'!$J34/90) -> 10.555556
H35: بيع | I35: موتير ليو | K35: 34 | L35: ='09-04'!$K35+('09-04'!$J35/90) -> 34
H36: بيع | I36: فاتورة | K36: 130 | L36: ='09-04'!$K36+('09-04'!$J36/90) -> 130
H37: بيع | I37: نربيج خلاط | J37: 500 | L37: ='09-04'!$K37+('09-04'!$J37/90) -> 5.5555556
H38: بيع | I38: ايزي مع صباب | J38: 150 | L38: ='09-04'!$K38+('09-04'!$J38/90) -> 1.6666667
H39: بيع | I39: غطاء ميوركس | J39: -270 | K39: 40 | L39: ='09-04'!$K39+('09-04'!$J39/90) -> 37
H40: بيع | I40: نحاتة | J40: 70 | L40: ='09-04'!$K40+('09-04'!$J40/90) -> 0.77777778
...

Sheet 10-04
I1: حركة الصندوق | J1: =SUM(J3:J18) -> -100 | K1: =SUM(K3:K18) -> 20 | L1: =SUM(L3:L18) -> 18.888889
H2: العملية | I2: البيان | J2: اللبناني | K2: الدولار | L2: مبيع $
H3: بيع | K3: 20 | L3: =K3+(J3/90) -> 20
H4: مصاريف | J4: -100 | L4: =K4+(J4/90) -> -1.1111111
H5: بيع | J5: -100 | K5: -20 | L5: =K5+(J5/90) -> -21.111111
H6: بيع | K6: 5 | L6: =K6+(J6/90) -> 5
H7: بيع | J7: 200 | L7: =K7+(J7/90) -> 2.2222222
H8: بيع | J8: 150 | L8: =K8+(J8/90) -> 1.6666667
H9: بيع | J9: -315 | K9: 5 | L9: =K9+(J9/90) -> 1.5
H10: بيع | J10: -315 | K10: 10 | L10: =K10+(J10/90) -> 6.5
H11: بيع | J11: 380 | L11: =K11+(J11/90) -> 4.2222222
H12: بيع | L12: =K12+(J12/90) -> 0
H13: بيع | L13: =K13+(J13/90) -> 0
H14: بيع | L14: =K14+(J14/90) -> 0
H15: بيع | L15: =K15+(J15/90) -> 0
H16: بيع | L16: =K16+(J16/90) -> 0
H17: بيع | L17: =K17+(J17/90) -> 0
A18: رصيد قديم من تاريخ | H18: بيع | L18: =K18+(J18/90) -> 0
A19: 09-04
A20: جرد اول النهار | I20: حركة الصندوق | J20: =SUM('10-04'!$J$22:$J$109) -> -1325 | K20: =SUM('10-04'!$K$22:$K$109) -> 52 | L20: =SUM('10-04'!$L$22:$L$109) -> 37.277778 | N20: جرد اخر النهار
A21: الفئة دولار | B21: العدد | C21: المجموع | D21: الفئة لبناني | E21: العدد | F21: المجموع | H21: العملية | I21: البيان | J21: اللبناني | K21: الدولار | L21: مبيع $ | N21: الفئة دولار | O21: العدد | P21: المجموع | Q21: الفئة لبناني | R21: العدد | S21: المجموع
A22: 1 | B22: 9 | C22: =A22*B22 -> 9 | D22: 5 | E22: 33 | F22: =D22*E22 -> 165 | H22: بيع | I22: كتر و قسطل | K22: 2 | L22: ='10-04'!$K22+('10-04'!$J22/90) -> 2 | N22: 1 | O22: 10 | P22: =N22*O22 -> 10 | Q22: 5 | R22: 33 | S22: =Q22*R22 -> 165
A23: 5 | B23: 1 | C23: =A23*B23 -> 5 | D23: 10 | E23: 21 | F23: =D23*E23 -> 210 | H23: بيع | I23: خالد أبو الدقن | K23: 20 | L23: ='10-04'!$K23+('10-04'!$J23/90) -> 20 | N23: 5 | O23: 4 | P23: =N23*O23 -> 20 | Q23: 10 | R23: 24 | S23: =Q23*R23 -> 240
A24: 10 | B24: 27 | C24: =A24*B24 -> 270 | D24: 20 | E24: 26 | F24: =D24*E24 -> 520 | H24: مصاريف | I24: بنزين عبد | J24: -300 | L24: ='10-04'!$K24+('10-04'!$J24/90) -> -3.3333333 | N24: 10 | O24: 28 | P24: =N24*O24 -> 280 | Q24: 20 | R24: 24 | S24: =Q24*R24 -> 480
A25: 20 | B25: 29 | C25: =A25*B25 -> 580 | D25: 50 | E25: 4 | F25: =D25*E25 -> 200 | H25: بيع | I25: ابو علي زريق | J25: 130 | K25: 20 | L25: ='10-04'!$K25+('10-04'!$J25/90) -> 21.444444 | N25: 20 | O25: 34 | P25: =N25*O25 -> 680 | Q25: 50 | R25: 3 | S25: =Q25*R25 -> 150
A26: 50 | B26: 2 | C26: =A26*B26 -> 100 | D26: 100 | E26: 54 | F26: =D26*E26 -> 5400 | H26: بيع | I26: ابو الياس | J26: -200 | K26: 35 | L26: ='10-04'!$K26+('10-04'!$J26/90) -> 32.777778 | N26: 50 | O26: 4 | P26: =N26*O26 -> 200 | Q26: 100 | R26: 55 | S26: =Q26*R26 -> 5500
A27: 100 | B27: 1 | C27: =A27*B27 -> 100 | D27: المجموع | F27: =SUM(F22:F26) -> 6495 | H27: بيع | I27: مصطفى | K27: 120 | L27: ='10-04'!$K27+('10-04'!$J27/90) -> 120 | N27: 100 | O27: 6 | P27: =N27*O27 -> 600 | Q27: المجموع | S27: =SUM(S22:S26) -> 6535
A28: المجموع | C28: =SUM(C22:C27) -> 1064 | H28: بيع | I28: وسام شقير | J28: -400 | K28: 10 | L28: ='10-04'!$K28+('10-04'!$J28/90) -> 5.5555556 | N28: المجموع | P28: =SUM(P22:P27) -> 1790
B29: 0 | D29: حركة الصندوق ل.ل | F29: {=INDIRECT("'"&$A$19&"'!J20")+J1} -> -1390 | H29: بيع | J29: 300 | L29: ='10-04'!$K29+('10-04'!$J29/90) -> 3.3333333 | Q29: حركة الصندوق ل.ل | S29: =SUM('10-04'!$J$22:$J$109) -> -1325
A30: حركة الصندوق $ | C30: {=INDIRECT("'"&$A$19&"'!K20")+K1} -> -74 | H30: بيع | I30: ورق حف | J30: 100 | L30: ='10-04'!$K30+('10-04'!$J30/90) -> 1.1111111 | N30: حركة الصندوق $ | P30: =SUM('10-04'!$K$22:$K$109) -> 52
D31: الفرق | F31: {=F27-F29-INDIRECT("'"&$A$19&"'!f27")} -> 0 | H31: بيع | I31: سبراي اسود مات | J31: 150 | L31: ='10-04'!$K31+('10-04'!$J31/90) -> 1.6666667 | Q31: الفرق | S31: =S27-S29-F27 -> 1365
A32: الفرق | C32: {=C28-C30-INDIRECT("'"&$A$19&"'!c28")} -> 0 | H32: بيع | I32: كاتو | J32: 360 | L32: ='10-04'!$K32+('10-04'!$J32/90) -> 4 | N32: الفرق | P32: =P28-P30-C28 -> 674
H33: بيع | I33: ابو الحسن موتير | K33: 130 | L33: ='10-04'!$K33+('10-04'!$J33/90) -> 130
H34: بيع | I34: ابو عماد الصالحاني | K34: 100 | L34: ='10-04'!$K34+('10-04'!$J34/90) -> 100
H35: بيع | I35: غطاء ميوركس | K35: 33 | L35: ='10-04'!$K35+('10-04'!$J35/90) -> 33
H36: بيع | K36: 2 | L36: ='10-04'!$K36+('10-04'!$J36/90) -> 2
H37: بيع | I37: طابة ومسكة وتلزيق | J37: -45 | K37: 15 | L37: ='10-04'!$K37+('10-04'!$J37/90) -> 14.5
H38: بيع | J38: 200 | L38: ='10-04'!$K38+('10-04'!$J38/90) -> 2.2222222
H39: بيع | I39: نربيج شطافة وبلجيكي | J39: -100 | K39: 10 | L39: ='10-04'!$K39+('10-04'!$J39/90) -> 8.8888889
H40: بيع | I40: عدة كبس صيني | J40: 600 | L40: ='10-04'!$K40+('10-04'!$J40/90) -> 6.6666667
...

Sheet 11-04
I1: حركة الصندوق | J1: =SUM(J3:J18) -> -220 | K1: =SUM(K3:K18) -> 40 | L1: =SUM(L3:L18) -> 37.555556
H2: العملية | I2: البيان | J2: اللبناني | K2: الدولار | L2: مبيع $
H3: بيع | I3: شطافة | J3: 100 | L3: =K3+(J3/90) -> 1.1111111
H4: بيع | I4: سبراي صدا | J4: 200 | L4: =K4+(J4/90) -> 2.2222222
H5: بيع | I5: اندركود | J5: 350 | L5: =K5+(J5/90) -> 3.8888889
H6: مصاريف | I6: بنزين | J6: -300 | L6: =K6+(J6/90) -> -3.3333333
H7: بيع | I7: ريشة سهم | K7: 5 | L7: =K7+(J7/90) -> 5
H8: بيع | I8: ابو حسين | J8: -400 | K8: 35 | L8: =K8+(J8/90) -> 30.555556
H9: بيع | I9: مرتجع | J9: -170 | L9: =K9+(J9/90) -> -1.8888889
H10: بيع | L10: =K10+(J10/90) -> 0
H11: بيع | L11: =K11+(J11/90) -> 0
H12: بيع | L12: =K12+(J12/90) -> 0
H13: بيع | L13: =K13+(J13/90) -> 0
H14: بيع | L14: =K14+(J14/90) -> 0
H15: بيع | L15: =K15+(J15/90) -> 0
H16: بيع | L16: =K16+(J16/90) -> 0
H17: بيع | L17: =K17+(J17/90) -> 0
A18: رصيد قديم من تاريخ | H18: بيع | L18: =K18+(J18/90) -> 0
A19: 10-04
A20: جرد اول النهار | I20: حركة الصندوق | J20: =SUM('11-04'!$J$22:$J$129) -> 2335 | K20: =SUM('11-04'!$K$22:$K$129) -> -90 | L20: =SUM('11-04'!$L$22:$L$129) -> -64.055556 | N20: جرد اخر النهار
A21: الفئة دولار | B21: العدد | C21: المجموع | D21: الفئة لبناني | E21: العدد | F21: المجموع | H21: العملية | I21: البيان | J21: اللبناني | K21: الدولار | L21: مبيع $ | N21: الفئة دولار | O21: العدد | P21: المجموع | Q21: الفئة لبناني | R21: العدد | S21: المجموع
A22: 1 | B22: 1 | C22: =A22*B22 -> 1 | D22: 5 | E22: 34 | F22: =D22*E22 -> 170 | H22: بيع | I22: غطايين ومجموعة شطافة | K22: 60 | L22: ='11-04'!$K22+('11-04'!$J22/90) -> 60 | N22: 1 | O22: 5 | P22: =N22*O22 -> 5 | Q22: 5 | R22: 35 | S22: =Q22*R22 -> 175
A23: 5 | B23: 3 | C23: =A23*B23 -> 15 | D23: 10 | E23: 24 | F23: =D23*E23 -> 240 | H23: سحب | I23: جبر | K23: -20 | L23: ='11-04'!$K23+('11-04'!$J23/90) -> -20 | N23: 5 | P23: =N23*O23 -> 0 | Q23: 10 | R23: 19 | S23: =Q23*R23 -> 190
A24: 10 | B24: 30 | C24: =A24*B24 -> 300 | D24: 20 | E24: 17 | F24: =D24*E24 -> 340 | H24: بيع | I24: احمد 3 | K24: 10 | L24: ='11-04'!$K24+('11-04'!$J24/90) -> 10 | N24: 10 | O24: 37 | P24: =N24*O24 -> 370 | Q24: 20 | R24: 15 | S24: =Q24*R24 -> 300
A25: 20 | B25: 37 | C25: =A25*B25 -> 740 | D25: 50 | E25: 2 | F25: =D25*E25 -> 100 | H25: بيع | I25: عمر فحام | K25: 69 | L25: ='11-04'!$K25+('11-04'!$J25/90) -> 69 | N25: 20 | O25: 35 | P25: =N25*O25 -> 700 | Q25: 50 | R25: 1 | S25: =Q25*R25 -> 50
A26: 50 | B26: 2 | C26: =A26*B26 -> 100 | D26: 100 | E26: 41 | F26: =D26*E26 -> 4100 | H26: بيع | I26: عباس | K26: 83 | L26: ='11-04'!$K26+('11-04'!$J26/90) -> 83 | N26: 50 | O26: 7 | P26: =N26*O26 -> 350 | Q26: 100 | R26: 188 | S26: =Q26*R26 -> 18800
A27: 100 | C27: =A27*B27 -> 0 | D27: المجموع | F27: =SUM(F22:F26) -> 4950 | H27: بيع | I27: رندال | J27: 100 | L27: ='11-04'!$K27+('11-04'!$J27/90) -> 1.1111111 | N27: 100 | O27: 17 | P27: =N27*O27 -> 1700 | Q27: المجموع | S27: =SUM(S22:S26) -> 19515
A28: المجموع | C28: =SUM(C22:C27) -> 1156 | H28: بيع | I28: غراء | J28: 200 | L28: ='11-04'!$K28+('11-04'!$J28/90) -> 2.2222222 | N28: المجموع | P28: =SUM(P22:P27) -> 3125
B29: 0 | D29: حركة الصندوق ل.ل | F29: {=INDIRECT("'"&$A$19&"'!J20")+J1} -> -1545 | H29: بيع | I29: موتير ليو حصان | K29: 64 | L29: ='11-04'!$K29+('11-04'!$J29/90) -> 64 | Q29: حركة الصندوق ل.ل | S29: =SUM('11-04'!$J$22:$J$129) -> 2335
A30: حركة الصندوق $ | C30: {=INDIRECT("'"&$A$19&"'!K20")+K1} -> 92 | H30: بيع | I30: طابة كهرباء | J30: 630 | L30: ='11-04'!$K30+('11-04'!$J30/90) -> 7 | N30: حركة الصندوق $ | P30: =SUM('11-04'!$K$22:$K$129) -> -90
D31: الفرق | F31: {=F27-F29-INDIRECT("'"&$A$19&"'!f27")} -> 0 | H31: سحب | I31: للحاج بيد حسام | K31: -40 | L31: ='11-04'!$K31+('11-04'!$J31/90) -> -40 | Q31: الفرق | S31: =S27-S29-F27 -> 12230
A32: الفرق | C32: {=C28-C30-INDIRECT("'"&$A$19&"'!c28")} -> 0 | H32: سحب | I32: للحاج بيد ابراهيم | K32: -40 | L32: ='11-04'!$K32+('11-04'!$J32/90) -> -40 | N32: الفرق | P32: =P28-P30-C28 -> 2059
H33: بيع | J33: 350 | L33: ='11-04'!$K33+('11-04'!$J33/90) -> 3.8888889
H34: بيع | I34: ورق حف | J34: 120 | L34: ='11-04'!$K34+('11-04'!$J34/90) -> 1.3333333
H35: بيع | I35: مصفاية | J35: 100 | L35: ='11-04'!$K35+('11-04'!$J35/90) -> 1.1111111
H36: بيع | I36: لقط | J36: -450 | K36: 10 | L36: ='11-04'!$K36+('11-04'!$J36/90) -> 5
H37: بيع | I37: خلاط | K37: 35 | L37: ='11-04'!$K37+('11-04'!$J37/90) -> 35
H38: بيع | I38: صباب مغسلة وسيليكون | J38: 400 | L38: ='11-04'!$K38+('11-04'!$J38/90) -> 4.4444444
H39: بيع | I39: طابة وسيلكون | K39: 20 | L39: ='11-04'!$K39+('11-04'!$J39/90) -> 20
H40: بيع | I40: فرق سدة | J40: 50 | L40: ='11-04'!$K40+('11-04'!$J40/90) -> 0.55555556
...

Sheet 13-04
I1: حركة الصندوق | J1: =SUM(J3:J18) -> 920 | K1: =SUM(K3:K18) -> 7 | L1: =SUM(L3:L18) -> 17.222222
H2: العملية | I2: البيان | J2: اللبناني | K2: الدولار | L2: مبيع $
H3: بيع | I3: مع الحاج | K3: 45 | L3: =K3+(J3/90) -> 45
H4: سحب | I4: مع الحاج | K4: -45 | L4: =K4+(J4/90) -> -45
H5: بيع | I5: بويا كيلو | K5: 7 | L5: =K5+(J5/90) -> 7
H6: بيع | I6: سكر ايطالي | J6: 500 | L6: =K6+(J6/90) -> 5.5555556
H7: بيع | J7: 120 | L7: =K7+(J7/90) -> 1.3333333
H8: بيع | I8: سكر زاوية | J8: 300 | L8: =K8+(J8/90) -> 3.3333333
H9: بيع | L9: =K9+(J9/90) -> 0
H10: بيع | L10: =K10+(J10/90) -> 0
H11: بيع | L11: =K11+(J11/90) -> 0
H12: بيع | L12: =K12+(J12/90) -> 0
H13: بيع | L13: =K13+(J13/90) -> 0
H14: بيع | L14: =K14+(J14/90) -> 0
H15: بيع | L15: =K15+(J15/90) -> 0
H16: بيع | L16: =K16+(J16/90) -> 0
H17: بيع | L17: =K17+(J17/90) -> 0
A18: رصيد قديم من تاريخ | H18: بيع | L18: =K18+(J18/90) -> 0
A19: 11-04
A20: جرد اول النهار | I20: حركة الصندوق | J20: =SUM('13-04'!$J$22:$J$137) -> -4090 | K20: =SUM('13-04'!$K$22:$K$137) -> -68 | L20: =SUM('13-04'!$L$22:$L$137) -> -113.44444 | N20: جرد اخر النهار
A21: الفئة دولار | B21: العدد | C21: المجموع | D21: الفئة لبناني | E21: العدد | F21: المجموع | H21: العملية | I21: البيان | J21: اللبناني | K21: الدولار | L21: مبيع $ | N21: الفئة دولار | O21: العدد | P21: المجموع | Q21: الفئة لبناني | R21: العدد | S21: المجموع
A22: 1 | B22: 3 | C22: =A22*B22 -> 3 | D22: 5 | E22: 35 | F22: =D22*E22 -> 175 | H22: بيع | I22: عبد | K22: 10 | L22: ='13-04'!$K22+('13-04'!$J22/90) -> 10 | N22: 1 | P22: =N22*O22 -> 0 | Q22: 5 | R22: 31 | S22: =Q22*R22 -> 155
A23: 5 | B23: 2 | C23: =A23*B23 -> 10 | D23: 10 | E23: 14 | F23: =D23*E23 -> 140 | H23: بيع | I23: قلب | J23: 100 | L23: ='13-04'!$K23+('13-04'!$J23/90) -> 1.1111111 | N23: 5 | O23: 1 | P23: =N23*O23 -> 5 | Q23: 10 | R23: 6 | S23: =Q23*R23 -> 60
A24: 10 | B24: 38 | C24: =A24*B24 -> 380 | D24: 20 | E24: 17 | F24: =D24*E24 -> 340 | H24: بيع | J24: -450 | K24: 5 | L24: ='13-04'!$K24+('13-04'!$J24/90) -> 0 | N24: 10 | O24: 48 | P24: =N24*O24 -> 480 | Q24: 20 | R24: 1 | S24: =Q24*R24 -> 20
A25: 20 | B25: 34 | C25: =A25*B25 -> 680 | D25: 50 | E25: 1 | F25: =D25*E25 -> 50 | H25: بيع | I25: مجموعتين شطافة | K25: 8 | L25: ='13-04'!$K25+('13-04'!$J25/90) -> 8 | N25: 20 | O25: 32 | P25: =N25*O25 -> 640 | Q25: 50 | R25: 1 | S25: =Q25*R25 -> 50
A26: 50 | C26: =A26*B26 -> 0 | D26: 100 | E26: 75 | F26: =D26*E26 -> 7500 | H26: بيع | I26: موتير ليو | J26: -180 | K26: 65 | L26: ='13-04'!$K26+('13-04'!$J26/90) -> 63 | N26: 50 | O26: 7 | P26: =N26*O26 -> 350 | Q26: 100 | R26: 69 | S26: =Q26*R26 -> 6900
A27: 100 | C27: =A27*B27 -> 0 | D27: المجموع | F27: =SUM(F22:F26) -> 8205 | H27: بيع | I27: غاندي | J27: 50 | K27: 222 | L27: ='13-04'!$K27+('13-04'!$J27/90) -> 222.55556 | N27: 100 | O27: 13 | P27: =N27*O27 -> 1300 | Q27: المجموع | S27: =SUM(S22:S26) -> 7185
A28: المجموع | C28: =SUM(C22:C27) -> 1073 | H28: بيع | I28: غال تنزيل | J28: -360 | K28: 20 | L28: ='13-04'!$K28+('13-04'!$J28/90) -> 16 | N28: المجموع | P28: =SUM(P22:P27) -> 2775
B29: 0 | D29: حركة الصندوق ل.ل | F29: {=INDIRECT("'"&$A$19&"'!J20")+J1} -> 3255 | H29: بيع | I29: سيليكون | J29: 370 | L29: ='13-04'!$K29+('13-04'!$J29/90) -> 4.1111111 | Q29: حركة الصندوق ل.ل | S29: =SUM('13-04'!$J$22:$J$137) -> -4090
A30: حركة الصندوق $ | C30: {=INDIRECT("'"&$A$19&"'!K20")+K1} -> -83 | H30: بيع | I30: اكسسوار | J30: -200 | K30: 10 | L30: ='13-04'!$K30+('13-04'!$J30/90) -> 7.7777778 | N30: حركة الصندوق $ | P30: =SUM('13-04'!$K$22:$K$137) -> -68
D31: الفرق | F31: {=F27-F29-INDIRECT("'"&$A$19&"'!f27")} -> 0 | H31: بيع | I31: احمد 3 | J31: 135 | K31: 10 | L31: ='13-04'!$K31+('13-04'!$J31/90) -> 11.5 | Q31: الفرق | S31: =S27-S29-F27 -> 3070
A32: الفرق | C32: {=C28-C30-INDIRECT("'"&$A$19&"'!c28")} -> 0 | H32: سحب | I32: للحاج | K32: -30 | L32: ='13-04'!$K32+('13-04'!$J32/90) -> -30 | N32: الفرق | P32: =P28-P30-C28 -> 1770
H33: بيع | K33: 4 | L33: ='13-04'!$K33+('13-04'!$J33/90) -> 4
H34: بيع | J34: 300 | L34: ='13-04'!$K34+('13-04'!$J34/90) -> 3.3333333
H35: بيع | J35: -135 | K35: 15 | L35: ='13-04'!$K35+('13-04'!$J35/90) -> 13.5
H36: بيع | I36: دفاش | K36: 40 | L36: ='13-04'!$K36+('13-04'!$J36/90) -> 40
H37: بيع | I37: ايبو | J37: -200 | K37: 10 | L37: ='13-04'!$K37+('13-04'!$J37/90) -> 7.7777778
H38: بيع | I38: متر | J38: -270 | K38: 5 | L38: ='13-04'!$K38+('13-04'!$J38/90) -> 2
H39: بيع | I39: حافظة | J39: 100 | L39: ='13-04'!$K39+('13-04'!$J39/90) -> 1.1111111
H40: بيع | J40: -135 | K40: 25 | L40: ='13-04'!$K40+('13-04'!$J40/90) -> 23.5
...

Sheet 14-04
I1: حركة الصندوق | J1: =SUM(J3:J18) -> 290 | K1: =SUM(K3:K18) -> 50 | L1: =SUM(L3:L18) -> 53.222222
H2: العملية | I2: البيان | J2: اللبناني | K2: الدولار | L2: مبيع $
H3: مصاريف | I3: كبايات | J3: -125 | L3: =K3+(J3/90) -> -1.3888889
H4: بيع | I4: سيليكون | J4: 350 | L4: =K4+(J4/90) -> 3.8888889
H5: بيع | I5: نبيل جلول | J5: -100 | K5: 50 | L5: =K5+(J5/90) -> 48.888889
H6: بيع | I6: سكر زاوية | J6: 210 | L6: =K6+(J6/90) -> 2.3333333
H7: بيع | I7: مطابقة | J7: -45 | L7: =K7+(J7/90) -> -0.5
H8: بيع | L8: =K8+(J8/90) -> 0
H9: بيع | L9: =K9+(J9/90) -> 0
H10: بيع | L10: =K10+(J10/90) -> 0
H11: بيع | L11: =K11+(J11/90) -> 0
H12: بيع | L12: =K12+(J12/90) -> 0
H13: بيع | L13: =K13+(J13/90) -> 0
H14: بيع | L14: =K14+(J14/90) -> 0
H15: بيع | L15: =K15+(J15/90) -> 0
H16: بيع | L16: =K16+(J16/90) -> 0
H17: بيع | L17: =K17+(J17/90) -> 0
A18: رصيد قديم من تاريخ | H18: بيع | L18: =K18+(J18/90) -> 0
A19: 13-04
A20: جرد اول النهار | I20: حركة الصندوق | J20: =SUM('14-04'!$J$22:$J$135) -> -240 | K20: =SUM('14-04'!$K$22:$K$135) -> 185 | L20: =SUM('14-04'!$L$22:$L$135) -> 182.33333 | N20: جرد اخر النهار
A21: الفئة دولار | B21: العدد | C21: المجموع | D21: الفئة لبناني | E21: العدد | F21: المجموع | H21: العملية | I21: البيان | J21: اللبناني | K21: الدولار | L21: مبيع $ | N21: الفئة دولار | O21: العدد | P21: المجموع | Q21: الفئة لبناني | R21: العدد | S21: المجموع
A22: 1 | C22: =A22*B22 -> 0 | D22: 5 | E22: 59 | F22: =D22*E22 -> 295 | H22: بيع | I22: احمد عيتاني | J22: 1800 | L22: ='14-04'!$K22+('14-04'!$J22/90) -> 20 | N22: 1 | P22: =N22*O22 -> 0 | Q22: 5 | R22: 57 | S22: =Q22*R22 -> 285
A23: 5 | B23: 1 | C23: =A23*B23 -> 5 | D23: 10 | E23: 53 | F23: =D23*E23 -> 530 | H23: جملة | I23: عماد شعبان | K23: 110 | L23: ='14-04'!$K23+('14-04'!$J23/90) -> 110 | N23: 5 | O23: 9 | P23: =N23*O23 -> 45 | Q23: 10 | R23: 42 | S23: =Q23*R23 -> 420
A24: 10 | B24: 46 | C24: =A24*B24 -> 460 | D24: 20 | E24: 39 | F24: =D24*E24 -> 780 | H24: بيع | I24: نص ليو | J24: -180 | K24: 65 | L24: ='14-04'!$K24+('14-04'!$J24/90) -> 63 | N24: 10 | O24: 47 | P24: =N24*O24 -> 470 | Q24: 20 | R24: 10 | S24: =Q24*R24 -> 200
A25: 20 | B25: 22 | C25: =A25*B25 -> 440 | D25: 50 | E25: 2 | F25: =D25*E25 -> 100 | H25: بيع | I25: احمد القزاز | J25: -675 | K25: 10 | L25: ='14-04'!$K25+('14-04'!$J25/90) -> 2.5 | N25: 20 | O25: 29 | P25: =N25*O25 -> 580 | Q25: 50 | S25: =Q25*R25 -> 0
A26: 50 | B26: 1 | C26: =A26*B26 -> 50 | D26: 100 | E26: 27 | F26: =D26*E26 -> 2700 | H26: بيع | I26: مرتجع | J26: -270 | K26: -10 | L26: ='14-04'!$K26+('14-04'!$J26/90) -> -13 | N26: 50 | O26: 2 | P26: =N26*O26 -> 100 | Q26: 100 | R26: 87 | S26: =Q26*R26 -> 8700
A27: 100 | B27: 1 | C27: =A27*B27 -> 100 | D27: المجموع | F27: =SUM(F22:F26) -> 4405 | H27: بيع | J27: -810 | K27: 10 | L27: ='14-04'!$K27+('14-04'!$J27/90) -> 1 | N27: 100 | O27: 12 | P27: =N27*O27 -> 1200 | Q27: المجموع | S27: =SUM(S22:S26) -> 9605
A28: المجموع | C28: =SUM(C22:C27) -> 1055 | H28: بيع | J28: 450 | L28: ='14-04'!$K28+('14-04'!$J28/90) -> 5 | N28: المجموع | P28: =SUM(P22:P27) -> 2395
B29: 0 | D29: حركة الصندوق ل.ل | F29: {=INDIRECT("'"&$A$19&"'!J20")+J1} -> -3800 | H29: بيع | K29: 140 | L29: ='14-04'!$K29+('14-04'!$J29/90) -> 140 | Q29: حركة الصندوق ل.ل | S29: =SUM('14-04'!$J$22:$J$135) -> -240
A30: حركة الصندوق $ | C30: {=INDIRECT("'"&$A$19&"'!K20")+K1} -> -18 | H30: بيع | I30: خالد ابو الدقن | K30: 35 | L30: ='14-04'!$K30+('14-04'!$J30/90) -> 35 | N30: حركة الصندوق $ | P30: =SUM('14-04'!$K$22:$K$135) -> 185
D31: الفرق | F31: {=F27-F29-INDIRECT("'"&$A$19&"'!f27")} -> 0 | H31: بيع | I31: مسكة شطافة 4 | J31: 400 | L31: ='14-04'!$K31+('14-04'!$J31/90) -> 4.4444444 | Q31: الفرق | S31: =S27-S29-F27 -> 5440
A32: الفرق | C32: {=C28-C30-INDIRECT("'"&$A$19&"'!c28")} -> 0 | H32: بيع | I32: ابو حسين | J32: -100 | K32: 130 | L32: ='14-04'!$K32+('14-04'!$J32/90) -> 128.88889 | N32: الفرق | P32: =P28-P30-C28 -> 1155
H33: بيع | I33: ابو كريم | J33: -250 | K33: 5 | L33: ='14-04'!$K33+('14-04'!$J33/90) -> 2.2222222
H34: بيع | J34: 400 | L34: ='14-04'!$K34+('14-04'!$J34/90) -> 4.4444444
H35: بيع | I35: بلال مكداشي | J35: 100 | K35: 100 | L35: ='14-04'!$K35+('14-04'!$J35/90) -> 101.11111
H36: بيع | J36: -100 | K36: 15 | L36: ='14-04'!$K36+('14-04'!$J36/90) -> 13.888889
H37: بيع | I37: ترابة و تنر | J37: 300 | K37: 5 | L37: ='14-04'!$K37+('14-04'!$J37/90) -> 8.3333333
H38: بيع | I38: سيليكون وترابة | K38: 5 | L38: ='14-04'!$K38+('14-04'!$J38/90) -> 5
H39: بيع | I39: طابة كهرباء | J39: 630 | L39: ='14-04'!$K39+('14-04'!$J39/90) -> 7
H40: بيع | I40: شادي مروة | K40: 3800 | L40: ='14-04'!$K40+('14-04'!$J40/90) -> 3800
...

Sheet 15-04
I1: حركة الصندوق | J1: =SUM(J3:J18) -> 150 | K1: =SUM(K3:K18) -> 100 | L1: =SUM(L3:L18) -> 101.66667
H2: العملية | I2: البيان | J2: اللبناني | K2: الدولار | L2: مبيع $
H3: بيع | I3: ترابة | J3: 200 | L3: =K3+(J3/90) -> 2.2222222
H4: بيع | I4: صباب كبس | J4: -100 | K4: 5 | L4: =K4+(J4/90) -> 3.8888889
H5: جملة | I5: عماد شعبان | K5: 90 | L5: =K5+(J5/90) -> 90
H6: بيع | I6: مطابقة | J6: 50 | K6: 5 | L6: =K6+(J6/90) -> 5.5555556
H7: بيع | L7: =K7+(J7/90) -> 0
H8: بيع | L8: =K8+(J8/90) -> 0
H9: بيع | L9: =K9+(J9/90) -> 0
H10: بيع | L10: =K10+(J10/90) -> 0
H11: بيع | L11: =K11+(J11/90) -> 0
H12: بيع | L12: =K12+(J12/90) -> 0
H13: بيع | L13: =K13+(J13/90) -> 0
H14: بيع | I14: مع الحاج | K14: 320 | L14: =K14+(J14/90) -> 320
H15: سحب | I15: مع الحاج | K15: -320 | L15: =K15+(J15/90) -> -320
H16: بيع | L16: =K16+(J16/90) -> 0
H17: بيع | L17: =K17+(J17/90) -> 0
A18: رصيد قديم من تاريخ | H18: بيع | L18: =K18+(J18/90) -> 0
A19: 14-04
A20: جرد اول النهار | I20: حركة الصندوق | J20: =SUM('15-04'!$J$22:$J$121) -> 55 | K20: =SUM('15-04'!$K$22:$K$121) -> -416 | L20: =SUM('15-04'!$L$22:$L$121) -> -415.38889 | N20: جرد اخر النهار
